================================================================================
DATA PREPARATION FRAMEWORK - ERROR REPORT
================================================================================
Dataset: cmb_cross_validation
Timestamp: 2025-10-23T13:30:15.083355+00:00
Stage: input_validation
Severity: ERROR
Error Type: validation_error

ERROR DETAILS:
----------------------------------------
Input validation failed: No uncertainty found for parameter 'R' and no covariance matrix provided

CONTEXT INFORMATION:
----------------------------------------
  file_exists: True
  file_size: 65
  metadata_available: True
  error_details: No uncertainty found for parameter 'R' and no covariance matrix provided
  dataset_info: {'raw_data_path': '/tmp/pytest-of-fabian/pytest-114/test_cmb_cross_validation0/cmb_cross_validation.txt', 'metadata_keys': ['source', 'version', 'description']}

SYSTEM INFORMATION:
----------------------------------------
  python_version: 3.12.3 (main, Aug 14 2025, 17:47:21) [GCC 13.3.0]
  platform: Linux-6.8.0-85-generic-x86_64-with-glibc2.39
  cpu_count: 32
  memory_total: 33224306688
  memory_available: 12018249728
  disk_usage: 46.4

SUGGESTED ACTIONS:
----------------------------------------
  1. Check file format and structure
  2. Verify file is not corrupted
  3. Review dataset documentation for expected format
  4. Check file permissions and accessibility

STACK TRACE:
----------------------------------------
Traceback (most recent call last):
  File "/home/fabian/PBUF/pipelines/data_preparation/engine/preparation_engine.py", line 319, in prepare_dataset
    if not module.validate_input(raw_data_path, metadata):
           ^^^^^^^^^^^^^^^^^^^^^^^^^^^^^^^^^^^^^^^^^^^^^^
  File "/home/fabian/PBUF/pipelines/data_preparation/derivation/cmb_derivation.py", line 83, in validate_input
    raise e
  File "/home/fabian/PBUF/pipelines/data_preparation/derivation/cmb_derivation.py", line 76, in validate_input
    self._validate_cmb_parameters(data, metadata)
  File "/home/fabian/PBUF/pipelines/data_preparation/derivation/cmb_derivation.py", line 185, in _validate_cmb_parameters
    raise ValueError(f"No uncertainty found for parameter '{param}' and no covariance matrix provided")
ValueError: No uncertainty found for parameter 'R' and no covariance matrix provided

================================================================================